Workbook

Sheet Contenido
B1: Consultoría para la Comisión Económica para América Latina y el Caribe
B2: Cuenta satélite de bioeconomía para países latinoamericanos
B3: Extracto de cuadros preliminares para socialización y consulta
B4: NO CITAR
B6: Elaborado por:
B7: Renato Vargas (Consultor de CEPAL)
B8: Andrés Mondaini (CEPAL)
B10: Cuadros de oferta y utilización bioeconómica agregados
B12: Argentina
B13: Brasil
B14: Chile
B15: Colombia
... B36: Formación Bruta de Capital

Sheet ARG
A1: Argentina | K1: Contenido
A2: Cuadros de oferta y utilización bioeconómica por producto y actividad económica
A3: Año 2018
A4: Precios corrientes
A5: Miles de pesos
A6: PRELIMINAR NO CITAR
D8: Producción / Consumo intermedio | L8: Exportaciones / Importaciones | M8: Ajuste CIF/FOB | N8: Impuestos menos subvenciones sobre los productos | O8: Márgenes de distribución | P8: Consumo final | Q8: Formación bruta de capital
D9: A | E9: B | F9: C | G9: D - E | H9: F | I9: G | J9: H - S | L9: - | M9: - | N9: - | O9: - | P9: - | Q9: -
A10: Cuadro | C10: Bioeconomía Productos | D10: Agricultura | E10: Minería | F10: Manufacturas | G10: Servicios básicos y agua | H10: Construcción | I10: Comercio | J10: Otros servicios | K10: Producción / Consumo intermedio Total | L10: - | M10: - | N10: - | O10: - | P10: - | Q10: -
A11: Oferta | B11: Producción | C11: Bioeconomía | D11: 1.3965777e+09 | E11: 81888147 | F11: 2.3356417e+09 | G11: 0 | H11: 0 | I11: 4619057.6 | J11: 668054.89 | K11: =SUM(D11:J11) -> 3.8193947e+09 | L11: 1.4650651e+08 | M11: 0 | N11: 6.7928866e+08 | O11: 1.1016863e+09 | R11: 5.7468761e+09
C12: Bioeconomía extendida | D12: 0 | E12: 0 | F12: 1.0489367e+09 | G12: 13918156 | H12: 0 | I12: 0 | J12: 43583914 | K12: =SUM(D12:J12) -> 1.1064388e+09 | L12: 3.6120831e+08 | M12: 0 | N12: 1.9603143e+08 | O12: 5.1178891e+08 | R12: 2.1754674e+09
C13: No bioeconomía | D13: 23146937 | E13: 9.6920518e+08 | F13: 2.9929067e+09 | G13: 8.1268888e+08 | H13: 1.1150938e+09 | I13: 3.0845649e+09 | J13: 1.0005864e+10 | K13: =SUM(D13:J13) -> 1.9003471e+10 | L13: 1.951621e+09 | M13: -82747541 | N13: 1.391367e+09 | O13: -1.6134752e+09 | R13: 2.0650236e+10
B14: Ajuste CIF/FOB | D14: 0 | E14: 0 | F14: 0 | G14: 0 | H14: 0 | I14: 0 | J14: 0 | K14: =SUM(D14:J14) -> 0 | L14: -82747541 | M14: 82747541 | N14: 0 | O14: 0 | R14: 0
B15: Compras directas en el exterior por residentes | D15: 0 | E15: 0 | F15: 0 | G15: 0 | H15: 0 | I15: 0 | J15: 0 | K15: =SUM(D15:J15) -> 0 | L15: 30627373 | M15: 0 | N15: 0 | O15: 0 | R15: 30627373
B16: Compras directas en el territorio nacional por no residentes | D16: 0 | E16: 0 | F16: 0 | G16: 0 | H16: 0 | I16: 0 | J16: 0 | K16: =SUM(D16:J16) -> 0 | L16: 0 | M16: 0 | N16: 0 | O16: 0 | R16: 0
A17: Oferta Total | D17: 1.4197247e+09 | E17: 1.0510933e+09 | F17: 6.3774851e+09 | G17: 8.2660704e+08 | H17: 1.1150938e+09 | I17: 3.089184e+09 | J17: 1.0050116e+10 | K17: =SUM(D17:J17) -> 2.3929304e+10 | L17: =SUM(L11:L13) -> 2.4593359e+09 | M17: 0 | N17: 2.2666871e+09 | O17: 0.80864191 | R17: 2.8603207e+10
A18: Utilización | B18: Consumo intermedio | C18: Bioeconomía | D18: 3.1684167e+08 | E18: 2014101.1 | F18: 1.2240967e+09 | G18: 16589.7 | H18: 9838191.6 | I18: 39880842 | J18: 3.8814291e+08 | K18: =SUM(D18:J18) -> 1.980831e+09 | L18: 9.7463403e+08 | P18: 2.5516152e+09 | Q18: 2.3979591e+08 | R18: 5.7468761e+09
C19: Bioeconomía extendida | D19: 1.3761952e+08 | E19: 16814984 | F19: 4.6710801e+08 | G19: 7029768.5 | H19: 9572929.3 | I19: 52218592 | J19: 2.5316164e+08 | K19: =SUM(D19:J19) -> 9.4352544e+08 | L19: 1.54574e+08 | P19: 9.1994828e+08 | Q19: 1.5741973e+08 | R19: 2.1754674e+09
C20: No bioeconomía | D20: 3.5107929e+08 | E20: 4.1169765e+08 | F20: 2.6131389e+09 | G20: 4.7975054e+08 | H20: 5.0647126e+08 | I20: 8.1708148e+08 | J20: 3.3476049e+09 | K20: =SUM(D20:J20) -> 8.5268241e+09 | L20: 9.5907651e+08 | P20: 9.111865e+09 | Q20: 2.0524703e+09 | R20: 2.0650236e+10
B21: Ajuste CIF/FOB | D21: 0 | E21: 0 | F21: 0 | G21: 0 | H21: 0 | I21: 0 | J21: 0 | K21: =SUM(D21:J21) -> 0 | L21: 0 | P21: 0 | Q21: 0 | R21: 0
B22: Compras directas en el exterior por residentes | D22: 0 | E22: 0 | F22: 0 | G22: 0 | H22: 0 | I22: 0 | J22: 0 | K22: =SUM(D22:J22) -> 0 | L22: 0 | P22: 30627373 | Q22: 0 | R22: 30627373
B23: Compras directas en el territorio nacional por no residentes | D23: 0 | E23: 0 | F23: 0 | G23: 0 | H23: 0 | I23: 0 | J23: 0 | K23: =SUM(D23:J23) -> 0 | L23: 40377443 | P23: -40377443 | Q23: 0 | R23: 0
A24: Utilización Total | D24: 8.0554049e+08 | E24: 4.3052673e+08 | F24: 4.3043435e+09 | G24: 4.867969e+08 | H24: 5.2588238e+08 | I24: 9.0918091e+08 | J24: 3.9889095e+09 | K24: =SUM(D24:J24) -> 1.145118e+10 | L24: 2.128662e+09 | P24: 1.2573679e+10 | Q24: 2.4496859e+09 | R24: 2.8603207e+10
A25: Valor Agregado | D25: 6.1418419e+08 | E25: 6.205666e+08 | F25: 2.0731415e+09 | G25: 3.3981014e+08 | H25: 5.8921143e+08 | I25: 2.1800031e+09 | J25: 6.0612067e+09 | K25: =SUM(D25:J25) -> 1.2478124e+10 | R25: 1.2478124e+10
A36: Indicadores
B38: Producción | C38: Bioeconomía | D38: =D11/D$17 -> 0.98369618 | E38: =E11/E$17 -> 0.077907589 | F38: =F11/F$17 -> 0.3662324 | G38: =G11/G$17 -> 0 | H38: =H11/H$17 -> 0 | I38: =I11/I$17 -> 0.0014952355 | J38: =J11/J$17 -> 6.6472355e-05 | K38: =K11/K$17 -> 0.15961161 | L38: =L11/L$17 -> 0.059571574 | N38: =N11/N$17 -> 0.29968348
C39: Bioeconomía extendida | D39: =D12/D$17 -> 0 | E39: =E12/E$17 -> 0 | F39: =F12/F$17 -> 0.16447498 | G39: =G12/G$17 -> 0.016837693 | H39: =H12/H$17 -> 0 | I39: =I12/I$17 -> 0 | J39: =J12/J$17 -> 0.0043366577 | K39: =K12/K$17 -> 0.046237817 | L39: =L12/L$17 -> 0.1468723 | N39: =N12/N$17 -> 0.086483675
C40: No bioeconomía | D40: =D13/D$17 -> 0.016303821 | E40: =E13/E$17 -> 0.92209241 | F40: =F13/F$17 -> 0.46929262 | G40: =G13/G$17 -> 0.98316231 | H40: =H13/H$17 -> 1 | I40: =I13/I$17 -> 0.99850476 | J40: =J13/J$17 -> 0.99559687 | K40: =K13/K$17 -> 0.79415058 | L40: =L13/L$17 -> 0.79355613 | N40: =N13/N$17 -> 0.61383285
B45: Consumo intermedio | C45: Bioeconomía | D45: =D18/D$24 -> 0.39332806 | E45: =E18/E$24 -> 0.0046782254 | F45: =F18/F$24 -> 0.28438637 | G45: =G18/G$24 -> 3.4079306e-05 | H45: =H18/H$24 -> 0.01870797 | I45: =I18/I$24 -> 0.043864584 | J45: =J18/J$24 -> 0.097305519 | K45: =K18/K$24 -> 0.1729805 | L45: =L18/L$24 -> 0.45786228 | P45: =P18/P$24 -> 0.20293308
C46: Bioeconomía extendida | D46: =D19/D$24 -> 0.17084122 | E46: =E19/E$24 -> 0.039056772 | F46: =F19/F$24 -> 0.10852015 | G46: =G19/G$24 -> 0.014440865 | H46: =H19/H$24 -> 0.018203556 | I46: =I19/I$24 -> 0.057434765 | J46: =J19/J$24 -> 0.063466378 | K46: =K19/K$24 -> 0.082395474 | L46: =L19/L$24 -> 0.072615567 | P46: =P19/P$24 -> 0.07316461
C47: No bioeconomía | D47: =D20/D$24 -> 0.43583072 | E47: =E20/E$24 -> 0.956265 | F47: =F20/F$24 -> 0.60709348 | G47: =G20/G$24 -> 0.98552506 | H47: =H20/H$24 -> 0.96308847 | I47: =I20/I$24 -> 0.89870065 | J47: =J20/J$24 -> 0.8392281 | K47: =K20/K$24 -> 0.74462402 | L47: =L20/L$24 -> 0.45055369 | P47: =P20/P$24 -> 0.72467775

Sheet BRA
A1: Brasil | K1: Contenido
A2: Cuadros de oferta y utilización bioeconómica por producto y actividad económica
A3: Año 2018
A4: Precios corrientes
A5: 1 000 000 R$
A6: PRELIMINAR NO CITAR
D8: Producción / Consumo intermedio | L8: Exportaciones / Importaciones | M8: Impuestos menos subvenciones sobre los productos | N8: Márgenes de distribución | O8: Consumo final | P8: Formación bruta de capital
D9: A | E9: B | F9: C | G9: D - E | H9: F | I9: G | J9: H - S | L9: - | M9: - | N9: - | O9: - | P9: -
A10: Cuadro | C10: Bioeconomía Productos | D10: Agricultura | E10: Minería | F10: Manufacturas | G10: Servicios básicos y agua | H10: Construcción | I10: Comercio | J10: Otros servicios | K10: Producción / Consumo intermedio Total | L10: - | M10: - | N10: - | O10: - | P10: -
A11: Oferta | B11: Producción | C11: Bioeconomía | D11: 578580 | E11: 172 | F11: 1116289 | G11: 0 | H11: 0 | I11: 46367 | J11: 1558 | K11: =SUM(D11:J11) -> 1742966 | L11: 59460 | M11: 206116 | N11: 426129 | Q11: 2434671
C12: Bioeconomía extendida | D12: 1942 | E12: 289 | F12: 561881 | G12: 81742 | H12: 26 | I12: 13440 | J12: 315886 | K12: =SUM(D12:J12) -> 975206 | L12: 167486 | M12: 164563 | N12: 248782 | Q12: 1556037
C13: No bioeconomía | D13: 7344 | E13: 356087 | F13: 1644029 | G13: 323617 | H13: 552047 | I13: 1235865 | J13: 5172849 | K13: =SUM(D13:J13) -> 9291838 | L13: 770528 | M13: 622312 | N13: -674911 | Q13: 10009767
A14: Oferta Total | D14: 587866 | E14: 356548 | F14: 3322199 | G14: 405359 | H14: 552073 | I14: 1295672 | J14: 5490293 | K14: =SUM(D14:J14) -> 12010010 | L14: 997474 | M14: 992991 | N14: 0 | Q14: 14000475
A15: Utilización | B15: Consumo intermedio | C15: Bioeconomía | D15: 49045 | E15: 10205 | F15: 573831 | G15: 4091 | H15: 15913 | I15: 41954 | J15: 247084 | K15: =SUM(D15:J15) -> 942123 | L15: 361386 | O15: 1117324 | P15: 13838 | Q15: 2434671
C16: Bioeconomía extendida | D16: 17001 | E16: 15110 | F16: 394855 | G16: 3520 | H16: 2589 | I16: 25459 | J16: 172933 | K16: =SUM(D16:J16) -> 631467 | L16: 61012 | O16: 804983 | P16: 58575 | Q16: 1556037
C17: No bioeconomía | D17: 23683 | E17: 170164 | F17: 1804611 | G17: 226315 | H17: 290291 | I17: 445212 | J17: 1464994 | K17: =SUM(D17:J17) -> 4425270 | L17: 602658 | O17: 3996974 | P17: 984865 | Q17: 10009767
A18: Utilización Total | D18: 89729 | E18: 195479 | F18: 2773297 | G18: 233926 | H18: 308793 | I18: 512625 | J18: 1885011 | K18: =SUM(D18:J18) -> 5998860 | L18: 1025056 | O18: 5919281 | P18: 1057278 | Q18: 14000475
A19: Valor Agregado | D19: 309611 | E19: 161069 | F19: 737428 | G19: 171433 | H19: 243280 | I19: 783047 | J19: 3605282 | K19: =SUM(D19:J19) -> 6011150 | Q19: 6011150
B29: Producción | C29: Bioeconomía | D29: =D11/D$14 -> 0.98420388 | E29: =E11/E$14 -> 0.00048240349 | F29: =F11/F$14 -> 0.33600907 | G29: =G11/G$14 -> 0 | H29: =H11/H$14 -> 0 | I29: =I11/I$14 -> 0.035786063 | J29: =J11/J$14 -> 0.00028377356 | K29: =K11/K$14 -> 0.14512611 | ... M29: =M11/M$14 -> 0.20757086
C30: Bioeconomía extendida | D30: =D12/D$14 -> 0.0033034739 | E30: =E12/E$14 -> 0.00081055005 | F30: =F12/F$14 -> 0.16912924 | G30: =G12/G$14 -> 0.20165335 | H30: =H12/H$14 -> 4.7095221e-05 | I30: =I12/I$14 -> 0.010372996 | J30: =J12/J$14 -> 0.057535363 | K30: =K12/K$14 -> 0.081199433 | ... M30: =M12/M$14 -> 0.16572456
C31: No bioeconomía | D31: =D13/D$14 -> 0.012492643 | E31: =E13/E$14 -> 0.99870705 | F31: =F13/F$14 -> 0.49486169 | G31: =G13/G$14 -> 0.79834665 | H31: =H13/H$14 -> 0.9999529 | I31: =I13/I$14 -> 0.95384094 | J31: =J13/J$14 -> 0.94218086 | K31: =K13/K$14 -> 0.77367446 | ... M31: =M13/M$14 -> 0.62670457
B33: Consumo intermedio | C33: Bioeconomía | D33: =D15/D$18 -> 0.54659029 | E33: =E15/E$18 -> 0.052205096 | F33: =F15/F$18 -> 0.20691293 | G33: =G15/G$18 -> 0.017488437 | H33: =H15/H$18 -> 0.051532904 | I33: =I15/I$18 -> 0.081841502 | J33: =J15/J$18 -> 0.13107828 | K33: =K15/K$18 -> 0.15705034 | L33: =L15/L$18 -> 0.35255245 | O33: =O15/O$18 -> 0.18876009
C34: Bioeconomía extendida | D34: =D16/D$18 -> 0.18947052 | E34: =E16/E$18 -> 0.077297306 | F34: =F16/F$18 -> 0.14237747 | G34: =G16/G$18 -> 0.015047494 | H34: =H16/H$18 -> 0.0083842574 | I34: =I16/I$18 -> 0.049663984 | J34: =J16/J$18 -> 0.091741109 | K34: =K16/K$18 -> 0.1052645 | L34: =L16/L$18 -> 0.059520651 | O34: =O16/O$18 -> 0.13599337
C35: No bioeconomía | D35: =D17/D$18 -> 0.26393919 | E35: =E17/E$18 -> 0.8704976 | F35: =F17/F$18 -> 0.65070961 | G35: =G17/G$18 -> 0.96746407 | H35: =H17/H$18 -> 0.94008284 | I35: =I17/I$18 -> 0.86849451 | J35: =J17/J$18 -> 0.77718061 | K35: =K17/K$18 -> 0.73768516 | L35: =L17/L$18 -> 0.5879269 | O35: =O17/O$18 -> 0.67524654

Sheet CHL
B1: Chile | K1: Contenido
A2: Cuadros de oferta y utilización bioeconómica por producto y actividad económica | B2: Cuadros de oferta y utilización bioeconómica por producto y actividad económica
B3: Año 2018
B4: Corrientes
B5: Miles de millones de pesos
A6: PRELIMINAR NO CITAR | B6: PRELIMINAR NO CITAR
E8: Producción / Consumo intermedio | M8: Exportaciones / Importaciones | N8: Impuestos menos subvenciones sobre los productos | O8: Márgenes de distribución | P8: Consumo final | Q8: Formación bruta de capital
E9: A | F9: B | G9: C | H9: D - E | I9: F | J9: G | K9: H - S | M9: - | N9: - | O9: - | P9: - | Q9: -
B10: Cuadro | D10: Bioeconomía Productos | E10: Agricultura | F10: Minería | G10: Manufacturas | H10: Servicios básicos y agua | I10: Construcción | J10: Comercio | K10: Otros servicios | L10: Producción / Consumo intermedio Total | M10: - | N10: - | O10: - | P10: - | Q10: -
A11: 1 | B11: Oferta | C11: Producción | D11: Bioeconomía | E11: 15173.2 | F11: 0 | G11: 23637.17 | H11: 0 | I11: 0 | J11: 726.53867 | K11: 5.3937354 | L11: =SUM(E11:K11) -> 39542.303 | M11: 4973.39 | N11: 4505.5261 | O11: 9924.0655 | R11: 58945.285
D12: Bioeconomía extendida | E12: 34.706252 | F12: 12.826481 | G12: 11106.058 | H12: 2092.188 | I12: 3.4076963 | J12: 116.62787 | K12: 7890.8933 | L12: =SUM(E12:K12) -> 21256.708 | M12: 7109.2427 | N12: 3453.38 | O12: 7079.8729 | R12: 38899.204
D13: No bioeconomía | E13: 21.710843 | F13: 30969.679 | G13: 23570.132 | H13: 11677.559 | I13: 27189.491 | J13: 35026.095 | K13: 140191.24 | L13: =SUM(E13:K13) -> 268645.9 | M13: 42902.758 | N13: 11001.038 | O13: -17003.938 | R13: 305545.76
A14: 2 | B14: Oferta Total | E14: 15229.618 | F14: 30982.505 | G14: 58313.361 | H14: 13769.747 | I14: 27192.899 | J14: 35869.262 | K14: 148087.52 | L14: =SUM(E14:K14) -> 329444.92 | M14: 54985.391 | N14: 18959.944 | O14: -1.4551915e-11 | R14: 403390.25
B15: Utilización | C15: Consumo intermedio | D15: Bioeconomía | E15: 4262.3807 | F15: 0.51718107 | G15: 11718.97 | H15: 34.085808 | I15: 20.038808 | J15: 358.38738 | K15: 2844.4141 | L15: =SUM(E15:K15) -> 19238.794 | M15: 12098.004 | P15: 27154.802 | Q15: 453.68489 | R15: 58945.285
D16: Bioeconomía extendida | E16: 858.81921 | F16: 149.91373 | G16: 3724.9782 | H16: 203.76273 | I16: 1359.1001 | J16: 478.12452 | K16: 3461.6575 | L16: =SUM(E16:K16) -> 10236.356 | M16: 5388.8971 | P16: 21965.668 | Q16: 1308.2829 | R16: 38899.204
A17: 3 | D17: No bioeconomía | E17: 3342.3759 | F17: 12720.18 | G17: 25047.147 | H17: 8086.1832 | I17: 13404.276 | J17: 16791.147 | K17: 48712.578 | L17: =SUM(E17:K17) -> 128103.89 | M17: 36912.167 | P17: 99952.685 | Q17: 40577.024 | R17: 305545.76
A18: Grand Total | B18: Utilización Total | E18: 8463.5758 | F18: 12870.611 | G18: 40491.095 | H18: 8324.0318 | I18: 14783.415 | J18: 17627.659 | K18: 55018.649 | L18: =SUM(E18:K18) -> 157579.04 | M18: 54399.068 | P18: 149073.15 | Q18: 42338.992 | R18: 403390.25
B19: Valor Agregado | E19: 6766.0417 | F19: 18111.894 | G19: 17822.266 | H19: 5445.7156 | I19: 12409.484 | J19: 18241.603 | K19: 93068.875 | L19: =SUM(E19:K19) -> 171865.88 | R19: 171865.88
C29: Producción | D29: Bioeconomía | E29: =E11/E$14 -> 0.99629557 | F29: =F11/F$14 -> 0 | G29: =G11/G$14 -> 0.40534742 | H29: =H11/H$14 -> 0 | I29: =I11/I$14 -> 0 | J29: =J11/J$14 -> 0.020255189 | K29: =K11/K$14 -> 3.6422618e-05 | L29: =L11/L$14 -> 0.12002706 | ... N29: =N11/N$14 -> 0.23763393
D30: Bioeconomía extendida | E30: =E12/E$14 -> 0.0022788656 | F30: =F12/F$14 -> 0.0004139911 | G30: =G12/G$14 -> 0.19045478 | H30: =H12/H$14 -> 0.15194091 | I30: =I12/I$14 -> 0.00012531567 | J30: =J12/J$14 -> 0.0032514712 | K30: =K12/K$14 -> 0.053285335 | L30: =L12/L$14 -> 0.064522799 | ... N30: =N12/N$14 -> 0.18214083
D31: No bioeconomía | E31: =E13/E$14 -> 0.0014255672 | F31: =F13/F$14 -> 0.99958601 | G31: =G13/G$14 -> 0.4041978 | H31: =H13/H$14 -> 0.84805909 | I31: =I13/I$14 -> 0.99987468 | J31: =J13/J$14 -> 0.97649334 | K31: =K13/K$14 -> 0.94667824 | L31: =L13/L$14 -> 0.81545015 | ... N31: =N13/N$14 -> 0.58022524
C33: Consumo intermedio | D33: Bioeconomía | E33: =E15/E$18 -> 0.50361464 | F33: =F15/F$18 -> 4.0183101e-05 | G33: =G15/G$18 -> 0.28942091 | H33: =H15/H$18 -> 0.0040948677 | I33: =I15/I$18 -> 0.0013554925 | J33: =J15/J$18 -> 0.020330969 | K33: =K15/K$18 -> 0.05169909 | L33: =L15/L$18 -> 0.1220898 | M33: =M15/M$18 -> 0.22239359 | P33: =P15/P$18 -> 0.18215756 | Q33: =Q15/Q$18 -> 0.010715534
D34: Bioeconomía extendida | E34: =E16/E$18 -> 0.10147238 | F34: =F16/F$18 -> 0.011647756 | G34: =G16/G$18 -> 0.091994998 | H34: =H16/H$18 -> 0.024478851 | I34: =I16/I$18 -> 0.091934111 | J34: =J16/J$18 -> 0.02712354 | K34: =K16/K$18 -> 0.062917893 | L34: =L16/L$18 -> 0.064960138 | M34: =M16/M$18 -> 0.099062305 | P34: =P16/P$18 -> 0.14734824 | Q34: =Q16/Q$18 -> 0.030900192
D35: No bioeconomía | E35: =E17/E$18 -> 0.39491298 | F35: =F17/F$18 -> 0.98831206 | G35: =G17/G$18 -> 0.61858409 | H35: =H17/H$18 -> 0.97142628 | I35: =I17/I$18 -> 0.9067104 | J35: =J17/J$18 -> 0.95254549 | K35: =K17/K$18 -> 0.88538302 | L35: =L17/L$18 -> 0.81295006 | M35: =M17/M$18 -> 0.67854411 | P35: =P17/P$18 -> 0.67049419 | Q35: =Q17/Q$18 -> 0.95838427

Sheet COL
A1: Colombia | K1: Contenido
A2: Cuadros de oferta y utilización bioeconómica por producto y actividad económica
A3: Año 2018
A4: Corrientes
A5: Miles de millones de pesos
A6: PRELIMINAR NO CITAR
D8: Producción / Consumo intermedio | L8: Exportaciones / Importaciones | M8: Ajuste CIF/FOB | N8: Impuestos menos subvenciones sobre los productos | O8: Márgenes de distribución | P8: Consumo final | Q8: Formación bruta de capital
D9: A | E9: B | F9: C | G9: D - E | H9: F | I9: G | J9: H - S | L9: - | M9: - | N9: - | O9: - | P9: - | Q9: -
A10: Cuadro | C10: Bioeconomía Productos | D10: Agricultura | E10: Minería | F10: Manufacturas | G10: Servicios básicos y agua | H10: Construcción | I10: Comercio | J10: Otros servicios | K10: Producción / Consumo intermedio Total | L10: - | M10: - | N10: - | O10: - | P10: - | Q10: -
A11: Oferta | B11: Producción | C11: Bioeconomía | D11: 92500 | E11: 0 | F11: 112149 | G11: 0 | H11: 0 | I11: 0 | J11: 1638 | K11: =SUM(D11:J11) -> 206287 | L11: 19843 | M11: 0 | N11: 15898 | O11: 52022 | P11: 0 | Q11: 0 | R11: 294050
C12: Bioeconomía extendida | D12: 4199 | E12: 14751 | F12: 56280 | G12: 42441 | H12: 0 | I12: 0 | J12: 67324 | K12: =SUM(D12:J12) -> 184995 | L12: 36014 | M12: 0 | N12: 14452 | O12: 25967 | P12: 0 | Q12: 0 | R12: 261428
C13: No bioeconomía | D13: 21546 | E13: 66677 | F13: 196551 | G13: 29292 | H13: 167458 | I13: 148769 | J13: 711320 | K13: =SUM(D13:J13) -> 1341613 | L13: 147974 | M13: 0 | N13: 60785 | O13: -77989 | P13: 0 | Q13: 0 | R13: 1472383
B14: Ajuste CIF/FOB | C14: - | D14: 0 | E14: 0 | F14: 0 | G14: 0 | H14: 0 | I14: 0 | J14: 0 | K14: =SUM(D14:J14) -> 0 | L14: -5309 | M14: 5309 | N14: 0 | O14: 0 | R14: 0
B15: Compras directas en el exterior por residentes | C15: - | D15: 0 | E15: 0 | F15: 0 | G15: 0 | H15: 0 | I15: 0 | J15: 0 | K15: =SUM(D15:J15) -> 0 | L15: 14392 | M15: 0 | N15: 0 | O15: 0 | R15: 14392
A16: Oferta Total | D16: 118245 | E16: 81428 | F16: 364980 | G16: 71733 | H16: 167458 | I16: 148769 | J16: 780282 | K16: =SUM(D16:J16) -> 1732895 | L16: 203831 | M16: 0 | N16: 91135 | O16: 0 | P16: 0 | Q16: 0 | R16: 2027861
A17: Utilización | B17: Consumo intermedio | C17: Bioeconomía | D17: 17057 | E17: 0 | F17: 67747 | G17: 0 | H17: 890 | I17: 234 | J17: 27010 | K17: =SUM(D17:J17) -> 112938 | L17: 22244 | M17: 0 | N17: 0 | O17: 0 | P17: 153008 | Q17: 5860 | R17: 294050
C18: Bioeconomía extendida | D18: 12102 | E18: 12960 | F18: 49194 | G18: 5239 | H18: 3845 | I18: 4715 | J18: 15717 | K18: =SUM(D18:J18) -> 103772 | L18: 16893 | M18: 0 | N18: 0 | O18: 0 | P18: 137381 | Q18: 3382 | R18: 261428
C19: No bioeconomía | D19: 12422 | E19: 25847 | F19: 137882 | G19: 33878 | H19: 97613 | I19: 57114 | J19: 254773 | K19: =SUM(D19:J19) -> 619529 | L19: 117919 | M19: 0 | N19: 0 | O19: 0 | P19: 534810 | Q19: 200125 | R19: 1472383
B20: Compras directas en el exterior por residentes | C20: - | D20: 0 | E20: 0 | F20: 0 | G20: 0 | H20: 0 | I20: 0 | J20: 0 | K20: =SUM(D20:J20) -> 0 | L20: 0 | P20: 5059 | Q20: 0 | R20: 5059
B21: Compras directas en el territorio nacional por no residentes | C21: - | D21: 0 | E21: 0 | F21: 0 | G21: 0 | H21: 0 | I21: 0 | J21: 0 | K21: =SUM(D21:J21) -> 0 | L21: 9333 | P21: 0 | Q21: 0 | R21: 9333
A22: Utilización Total | D22: 41581 | E22: 38807 | F22: 254823 | G22: 39117 | H22: 102348 | I22: 62063 | J22: 297500 | K22: =SUM(D22:J22) -> 836239 | L22: 157056 | M22: 0 | N22: 0 | O22: 0 | P22: 825199 | Q22: 209367 | R22: 2027861
A23: Valor Agregado | D23: 76664 | E23: 42621 | F23: 110157 | G23: 32616 | H23: 65110 | I23: 86706 | J23: 482782 | K23: =SUM(D23:J23) -> 896656 | R23: 896656
B33: Producción | C33: Bioeconomía | D33: =D11/D$16 -> 0.78227409 | E33: =E11/E$16 -> 0 | F33: =F11/F$16 -> 0.30727437 | G33: =G11/G$16 -> 0 | H33: =H11/H$16 -> 0 | I33: =I11/I$16 -> 0 | J33: =J11/J$16 -> 0.002099241 | K33: =K11/K$16 -> 0.11904183 | L33: =L11/L$16 -> 0.097350256 | N33: =N11/N$16 -> 0.17444451
C34: Bioeconomía extendida | D34: =D12/D$16 -> 0.035511015 | E34: =E12/E$16 -> 0.1811539 | F34: =F12/F$16 -> 0.15420023 | G34: =G12/G$16 -> 0.59165238 | H34: =H12/H$16 -> 0 | I34: =I12/I$16 -> 0 | J34: =J12/J$16 -> 0.086281626 | K34: =K12/K$16 -> 0.10675488 | L34: =L12/L$16 -> 0.17668559 | N34: =N12/N$16 -> 0.15857793
C35: No bioeconomía | D35: =D13/D$16 -> 0.18221489 | E35: =E13/E$16 -> 0.8188461 | F35: =F13/F$16 -> 0.5385254 | G35: =G13/G$16 -> 0.40834762 | H35: =H13/H$16 -> 1 | I35: =I13/I$16 -> 1 | J35: =J13/J$16 -> 0.91161913 | K35: =K13/K$16 -> 0.77420328 | L35: =L13/L$16 -> 0.72596416 | N35: =N13/N$16 -> 0.66697756
B36: Ajuste CIF/FOB | C36: -
B37: Compras directas en el exterior por residentes | C37: -
B39: Consumo intermedio | C39: Bioeconomía | D39: =D17/D$22 -> 0.41021139 | E39: =E17/E$22 -> 0 | F39: =F17/F$22 -> 0.26585905 | G39: =G17/G$22 -> 0 | H39: =H17/H$22 -> 0.0086958221 | I39: =I17/I$22 -> 0.0037703624 | J39: =J17/J$22 -> 0.090789916 | K39: =K17/K$22 -> 0.13505469 | L39: =L17/L$22 -> 0.14163101 | P39: =P17/P$22 -> 0.18541952 | Q39: =Q17/Q$22 -> 0.027989129
C40: Bioeconomía extendida | D40: =D18/D$22 -> 0.29104639 | E40: =E18/E$22 -> 0.33396037 | F40: =F18/F$22 -> 0.19305165 | G40: =G18/G$22 -> 0.13393154 | H40: =H18/H$22 -> 0.037567906 | I40: =I18/I$22 -> 0.075971191 | J40: =J18/J$22 -> 0.052830252 | K40: =K18/K$22 -> 0.12409371 | L40: =L18/L$22 -> 0.10756036 | P40: =P18/P$22 -> 0.16648227 | Q40: =Q18/Q$22 -> 0.016153453
C41: No bioeconomía | D41: =D19/D$22 -> 0.29874221 | E41: =E19/E$22 -> 0.66603963 | F41: =F19/F$22 -> 0.54108931 | G41: =G19/G$22 -> 0.86606846 | H41: =H19/H$22 -> 0.95373627 | I41: =I19/I$22 -> 0.92025845 | J41: =J19/J$22 -> 0.85637983 | K41: =K19/K$22 -> 0.7408516 | L41: =L19/L$22 -> 0.75080863 | P41: =P19/P$22 -> 0.64809822 | Q41: =Q19/Q$22 -> 0.95585742

Sheet CRI
A1: Costa Rica | K1: Contenido
A2: Cuadros de oferta y utilización bioeconómica por producto y actividad económica
A3: Año 2018
A4: Corrientes
A5: Millones de colones
A6: PRELIMINAR NO CITAR
D8: Producción / Consumo Intermedio | L8: Importaciones / Exportaciones | M8: Impuestos sobre los productos | N8: Subvenciones sobre los productos | O8: Márgenes de distribución | P8: Gasto de consumo final de los hogares | Q8: Gasto de consumo final ISFLSH | R8: Gasto de consumo final de Gobierno General | S8: Formación Bruta de Capital / Variación de Existencias
D9: A | E9: B | F9: C | G9: D - E | H9: F | I9: G | J9: H - S | L9: - | M9: - | N9: - | O9: - | P9: - | Q9: - | R9: - | S9: -
A10: Cuadro | B10: Áreas Transaccionales Filas | C10: Bioeconomía Productos | D10: Agricultura | E10: Minería | F10: Manufacturas | G10: Servicios básicos y agua | H10: Construcción | I10: Comercio | J10: Otros servicios | K10: Producción / Consumo intermedio Total | L10: - | M10: - | N10: - | O10: - | P10: - | Q10: - | R10: - | S10: -
A11: Oferta | B11: Producción | C11: Bioeconomía | D11: 3286444.4 | E11: 43.085828 | F11: 5968579.6 | G11: 56042.168 | H11: 241.5913 | I11: 35273.978 | J11: 1961203.1 | K11: =SUM(D11:J11) -> 11307828 | L11: 3240197.3 | M11: 858203.58 | N11: 0 | O11: 2438165.7 | T11: 17844395
C12: Bioeconomía extendida | D12: 12496.142 | E12: 214565.58 | F12: 728845.46 | G12: 352952.96 | H12: 2223.3542 | I12: 4506897.4 | J12: 756578.21 | K12: =SUM(D12:J12) -> 6574559.2 | L12: 779920.9 | M12: 113302.69 | N12: 0 | O12: -4495923.5 | T12: 2971859.3
C13: No bioeconomía | D13: 0 | E13: 14189.265 | F13: 4724452.3 | G13: 1052292.5 | H13: 4726221.7 | I13: 731126.8 | J13: 28909879 | K13: =SUM(D13:J13) -> 40158161 | L13: 7939228.7 | M13: 1653036.7 | N13: 0 | O13: 2057757.8 | T13: 51808184
B14: Ajustes CIF/FOB sobre importaciones Oferta | C14: - | D14: 0 | E14: 0 | F14: 0 | G14: 0 | H14: 0 | I14: 0 | J14: 0 | K14: =SUM(D14:J14) -> 0 | L14: 0 | M14: 0 | N14: 0 | O14: 0 | T14: 0
A15: Oferta Total | D15: 3298940.6 | E15: 228797.93 | F15: 11421877 | G15: 1461287.6 | H15: 4728686.6 | I15: 5273298.2 | J15: 31627660 | K15: =SUM(D15:J15) -> 58040548 | L15: 11959347 | M15: 2624543 | N15: 0 | O15: -5.3551048e-09 | T15: 72624438
A16: Utilización | B16: Consumo intermedio | C16: Bioeconomía | D16: 788279.98 | E16: 1771.2303 | F16: 2699860.4 | G16: 11753.299 | H16: 83486.238 | I16: 114244.13 | J16: 1476975.2 | K16: =SUM(D16:J16) -> 5176370.5 | L16: 3841690.4 | P16: 8351766.9 | Q16: 14365.33 | R16: 262452.2 | S16: 197749.23 | T16: 17844395
C17: Bioeconomía extendida | D17: 343825.21 | E17: 7216.2832 | F17: 476001.02 | G17: 47526.057 | H17: 261072.21 | I17: 56276.174 | J17: 400825.82 | K17: =SUM(D17:J17) -> 1592742.8 | L17: 511400.89 | P17: 778261.88 | Q17: 2967.5141 | R17: 0 | S17: 86486.243 | T17: 2971859.3
C18: No bioeconomía | D18: 551997.2 | E18: 98533.752 | F18: 3951501.8 | G18: 438661.14 | H18: 2719455.8 | I18: 1773683 | J18: 8347426.7 | K18: =SUM(D18:J18) -> 17881259 | L18: 7797738.4 | P18: 13840698 | Q18: 386475.1 | R18: 5570395.8 | S18: 6331618.1 | T18: 51808184
B19: Ajustes CIF/FOB sobre importaciones Utilización | C19: - | D19: 0 | E19: 0 | F19: 0 | G19: 0 | H19: 0 | I19: 0 | J19: 0 | K19: =SUM(D19:J19) -> 0 | L19: 0 | P19: 0 | Q19: 0 | R19: 0 | S19: 0 | T19: 0
A20: Utilización Total | D20: 1684102.4 | E20: 107521.27 | F20: 7127363.2 | G20: 497940.5 | H20: 3064014.3 | I20: 1944203.3 | J20: 10225228 | K20: =SUM(D20:J20) -> 24650373 | L20: 12150830 | P20: 22970726 | Q20: 403807.94 | R20: 5832848 | S20: 6615853.6 | T20: 72624438
A21: Valor Agregado | D21: 1614838.2 | E21: 121276.67 | F21: 4294514.1 | G21: 963347.12 | H21: 1664672.4 | I21: 3329094.9 | J21: 21402432 | K21: =SUM(D21:J21) -> 33390176 | T21: 33390176
A22: Empleo Total | D22: 226565.24 | E22: 4915.3695 | F22: 243015.95 | G22: 25522.534 | H22: 150849.39 | I22: 417819.09 | J22: 1258626.5 | K22: =SUM(D22:J22) -> 2327314.1 | T22: 2327314.1
B32: Producción | C32: Bioeconomía | D32: =D11/D$15 -> 0.99621207 | E32: =E11/E$15 -> 0.00018831389 | F32: =F11/F$15 -> 0.5225568 | G32: =G11/G$15 -> 0.038351224 | H32: =H11/H$15 -> 5.1090571e-05 | I32: =I11/I$15 -> 0.0066891681 | J32: =J11/J$15 -> 0.062009112 | K32: =K11/K$15 -> 0.19482635 | ... M32: =M11/M$15 -> 0.32699162
C33: Bioeconomía extendida | D33: =D12/D$15 -> 0.0037879258 | E33: =E12/E$15 -> 0.93779511 | F33: =F12/F$15 -> 0.063811354 | G33: =G12/G$15 -> 0.24153558 | H33: =H12/H$15 -> 0.00047018429 | I33: =I12/I$15 -> 0.85466387 | J33: =J12/J$15 -> 0.02392141 | K33: =K12/K$15 -> 0.11327528 | ... M33: =M12/M$15 -> 0.043170445
C34: No bioeconomía | D34: =D13/D$15 -> 0 | E34: =E13/E$15 -> 0.062016578 | F34: =F13/F$15 -> 0.41363185 | G34: =G13/G$15 -> 0.72011319 | H34: =H13/H$15 -> 0.99947873 | I34: =I13/I$15 -> 0.13864697 | J34: =J13/J$15 -> 0.91406948 | K34: =K13/K$15 -> 0.69189838 | ... M34: =M13/M$15 -> 0.62983793
B35: Ajustes CIF/FOB sobre importaciones Oferta | C35: -
B37: Consumo intermedio | C37: Bioeconomía | D37: =D16/D$20 -> 0.46807129 | E37: =E16/E$20 -> 0.016473302 | F37: =F16/F$20 -> 0.37880213 | G37: =G16/G$20 -> 0.023603823 | H37: =H16/H$20 -> 0.02724734 | I37: =I16/I$20 -> 0.058761411 | J37: =J16/J$20 -> 0.14444424 | K37: =K16/K$20 -> 0.20999157 | L37: =L16/L$20 -> 0.31616692 | P37: =P16/P$20 -> 0.36358306 | Q37: =Q16/Q$20 -> 0.035574659 | R37: =R16/R$20 -> 0.044995549 | S37: =S16/S$20 -> 0.029890206
C38: Bioeconomía extendida | D38: =D17/D$20 -> 0.20415933 | E38: =E17/E$20 -> 0.067114939 | F38: =F17/F$20 -> 0.066785009 | G38: =G17/G$20 -> 0.095445254 | H38: =H17/H$20 -> 0.085205937 | I38: =I17/I$20 -> 0.028945622 | J38: =J17/J$20 -> 0.039199696 | K38: =K17/K$20 -> 0.064613334 | L38: =L17/L$20 -> 0.042087734 | P38: =P17/P$20 -> 0.033880595 | Q38: =Q17/Q$20 -> 0.0073488254 | R38: =R17/R$20 -> 0 | S38: =S17/S$20 -> 0.013072575
C39: No bioeconomía | D39: =D18/D$20 -> 0.32776938 | E39: =E18/E$20 -> 0.91641176 | F39: =F18/F$20 -> 0.55441286 | G39: =G18/G$20 -> 0.88095092 | H39: =H18/H$20 -> 0.88754672 | I39: =I18/I$20 -> 0.91229297 | J39: =J18/J$20 -> 0.81635607 | K39: =K18/K$20 -> 0.72539509 | L39: =L18/L$20 -> 0.64174535 | P39: =P18/P$20 -> 0.60253635 | Q39: =Q18/Q$20 -> 0.95707652 | R39: =R18/R$20 -> 0.95500445 | S39: =S18/S$20 -> 0.95703722

Sheet DOM
A1: República Dominicana | K1: Contenido
A2: Cuadros de oferta y utilización bioeconómica por producto y actividad económica
A3: Año 2016
A4: Precios corrientes
A5: Millones de RD$
A6: PRELIMINAR NO CITAR
D8: Producción / Consumo intermedio | L8: Exportaciones / Importaciones | M8: Ajuste CIF/FOB | N8: Impuestos menos subvenciones sobre los productos | O8: Márgenes de distribución | P8: Consumo final | Q8: Formación bruta de capital
D9: A | E9: B | F9: C | G9: D - E | H9: F | I9: G | J9: H - S | L9: - | M9: - | N9: - | O9: - | P9: - | Q9: -
A10: Cuadro | C10: Bioeconomía Productos | D10: Agricultura | E10: Minería | F10: Manufacturas | G10: Servicios básicos y agua | H10: Construcción | I10: Comercio | J10: Otros servicios | K10: Producción / Consumo intermedio Total | L10: - | M10: - | N10: - | O10: - | P10: - | Q10: -
A11: Oferta | B11: Producción | C11: Bioeconomía | D11: 259361.28 | E11: 0 | F11: 498485.6 | G11: 0 | H11: 0 | I11: 0 | J11: 4.8260709 | K11: =SUM(D11:J11) -> 757851.7 | L11: 126322.01 | M11: 0 | N11: 75536.056 | O11: 292867.59 | P11: 0 | Q11: 0 | R11: 1252577.4
C12: Bioeconomía extendida | D12: 10007.479 | E12: 0 | F12: 139799.86 | G12: 12522.463 | H12: 0 | I12: 3277.4522 | J12: 624243.97 | K12: =SUM(D12:J12) -> 789851.22 | L12: 113669.94 | M12: 0 | N12: 35269.641 | O12: 42407.06 | P12: 0 | Q12: 0 | R12: 981197.86
C13: No bioeconomía | D13: 0 | E13: 103258.25 | F13: 474290.08 | G13: 118511.38 | H13: 655446.6 | I13: 527475.3 | J13: 1708891.8 | K13: =SUM(D13:J13) -> 3587873.4 | L13: 725171.76 | M13: -60071.529 | N13: 135611.42 | O13: -335274.65 | P13: 0 | Q13: 0 | R13: 4113381.9
B14: Ajuste CIF/FOB | C14: - | D14: 0 | E14: 0 | F14: 0 | G14: 0 | H14: 0 | I14: 0 | J14: 0 | K14: =SUM(D14:J14) -> 0 | L14: -60071.529 | M14: 60071.529 | N14: 0 | O14: 0 | R14: 0
B15: - | C15: - | D15: 0 | E15: 0 | F15: 0 | G15: 0 | H15: 0 | I15: 0 | J15: 0 | K15: =SUM(D15:J15) -> 0 | L15: 4452.363 | M15: 0 | N15: 0 | O15: 0 | R15: 4452.363
A16: Oferta Total | D16: 269368.76 | E16: 103258.25 | F16: 1112575.5 | G16: 131033.84 | H16: 655446.6 | I16: 530752.75 | J16: 2333140.6 | K16: =SUM(D16:J16) -> 5135576.3 | L16: =SUM(L11:L13) -> 965163.71 | M16: -2.1827873e-11 | N16: 246417.11 | O16: -6.4028427e-10 | R16: 6347157.1
A17: Utilización | B17: Consumo intermedio | C17: Bioeconomía | D17: 35469.908 | E17: 5.5703963 | F17: 218311.62 | G17: 23.276693 | H17: 3426.3629 | I17: 163.83122 | J17: 80812.875 | K17: =SUM(D17:J17) -> 338213.44 | L17: 109036.58 | P17: 797079.39 | Q17: 8247.9388 | R17: 1252577.4
C18: Bioeconomía extendida | D18: 34520.012 | E18: 16629.949 | F18: 83123.438 | G18: 21631.39 | H18: 18796.252 | I18: 41702.679 | J18: 196868.78 | K18: =SUM(D18:J18) -> 413272.5 | L18: 211056.95 | P18: 355250.29 | Q18: 1618.1308 | R18: 981197.86
C19: No bioeconomía | D19: 7324.1105 | E19: 17651.078 | F19: 308314.82 | G19: 49158.925 | H19: 303512.96 | I19: 114739.97 | J19: 342513.12 | K19: =SUM(D19:J19) -> 1143215 | L19: 513696.47 | P19: 1665229.1 | Q19: 791241.4 | R19: 4113381.9
B20: Ajuste CIF/FOB | C20: - | D20: 0 | E20: 0 | F20: 0 | G20: 0 | H20: 0 | I20: 0 | J20: 0 | K20: =SUM(D20:J20) -> 0 | L20: 0 | P20: 0 | Q20: 0 | R20: 0
B21: Compras directas en el territorio nacional por no residentes | C21: - | D21: 0 | E21: 0 | F21: 0 | G21: 0 | H21: 0 | I21: 0 | J21: 0 | K21: =SUM(D21:J21) -> 0 | L21: 29568.312 | P21: -25115.949 | Q21: 0 | R21: 4452.363
A22: Utilización Total | D22: 77314.031 | E22: 34286.598 | F22: 609749.87 | G22: 70813.592 | H22: 325735.58 | I22: 156606.48 | J22: 620194.77 | K22: =SUM(D22:J22) -> 1894700.9 | L22: 833790 | P22: 2817558.7 | Q22: 801107.47 | R22: 6347157.1
A23: Valor Agregado | D23: 192054.73 | E23: 68971.652 | F23: 502825.66 | G23: 60220.246 | H23: 329711.02 | I23: 374146.28 | J23: 1712945.8 | K23: =SUM(D23:J23) -> 3240875.4 | R23: 3240875.4
A24: Empleo Total | D24: 573019 | E24: 5787.7125 | F24: 465859.59 | G24: 34981.81 | H24: 337034.17 | I24: 821555.16 | J24: 2338004.2 | K24: =SUM(D24:J24) -> 4576241.6 | R24: 4576241.6
B34: Producción | C34: Bioeconomía | D34: =D11/D$16 -> 0.96284841 | E34: =E11/E$16 -> 0 | F34: =F11/F$16 -> 0.44804652 | G34: =G11/G$16 -> 0 | H34: =H11/H$16 -> 0 | I34: =I11/I$16 -> 0 | J34: =J11/J$16 -> 2.068487e-06 | K34: =K11/K$16 -> 0.14756897 | L34: =L11/L$16 -> 0.13088144 | N34: =N11/N$16 -> 0.30653738
C35: Bioeconomía extendida | D35: =D12/D$16 -> 0.037151595 | E35: =E12/E$16 -> 0 | F35: =F12/F$16 -> 0.12565426 | G35: =G12/G$16 -> 0.095566633 | H35: =H12/H$16 -> 0 | I35: =I12/I$16 -> 0.0061751017 | J35: =J12/J$16 -> 0.26755523 | K35: =K12/K$16 -> 0.15379992 | L35: =L12/L$16 -> 0.1177727 | N35: =N12/N$16 -> 0.14312983
C36: No bioeconomía | D36: =D13/D$16 -> 0 | E36: =E13/E$16 -> 1 | F36: =F13/F$16 -> 0.42629922 | G36: =G13/G$16 -> 0.90443337 | H36: =H13/H$16 -> 1 | I36: =I13/I$16 -> 0.9938249 | J36: =J13/J$16 -> 0.7324427 | K36: =K13/K$16 -> 0.69863111 | L36: =L13/L$16 -> 0.75134586 | N36: =N13/N$16 -> 0.55033279
B37: Ajuste CIF/FOB | C37: -
B38: - | C38: -
B40: Consumo intermedio | C40: Bioeconomía | D40: =D17/D$22 -> 0.45877711 | E40: =E17/E$22 -> 0.00016246571 | F40: =F17/F$22 -> 0.35803471 | G40: =G17/G$22 -> 0.00032870375 | H40: =H17/H$22 -> 0.010518848 | I40: =I17/I$22 -> 0.0010461331 | J40: =J17/J$22 -> 0.13030241 | K40: =K17/K$22 -> 0.17850492 | L40: =L17/L$22 -> 0.13077224 | P40: =P17/P$22 -> 0.28289717 | Q40: =Q17/Q$22 -> 0.010295671
C41: Bioeconomía extendida | D41: =D18/D$22 -> 0.44649092 | E41: =E18/E$22 -> 0.48502769 | F41: =F18/F$22 -> 0.13632383 | G41: =G18/G$22 -> 0.30546947 | H41: =H18/H$22 -> 0.057704019 | I41: =I18/I$22 -> 0.26628962 | J41: =J18/J$22 -> 0.31743056 | K41: =K18/K$22 -> 0.21812018 | L41: =L18/L$22 -> 0.25312962 | P41: =P18/P$22 -> 0.12608443 | Q41: =Q18/Q$22 -> 0.0020198673
C42: No bioeconomía | D42: =D19/D$22 -> 0.094731971 | E42: =E19/E$22 -> 0.51480984 | F42: =F19/F$22 -> 0.50564146 | G42: =G19/G$22 -> 0.69420183 | H42: =H19/H$22 -> 0.93177713 | I42: =I19/I$22 -> 0.73266425 | J42: =J19/J$22 -> 0.55226702 | K42: =K19/K$22 -> 0.6033749 | L42: =L19/L$22 -> 0.61609814 | P42: =P19/P$22 -> 0.5910184 | Q42: =Q19/Q$22 -> 0.98768446

Sheet ECU
A1: Ecuador | K1: Contenido
A2: Cuadros de oferta y utilización bioeconómica por producto y actividad económica
A3: Año 2018
A4: Precios corrientes
A5: Miles de dólares y puestos de trabajo
A6: PRELIMINAR NO CITAR
D8: Producción / Consumo intermedio | L8: Exportaciones / Importaciones | M8: Ajuste CIF/FOB | N8: Impuestos menos subvenciones sobre los productos | O8: Márgenes de distribución | P8: Consumo final | Q8: Formación bruta de capital
D9: A | E9: B | F9: C | G9: D - E | H9: F | I9: G | J9: H - S | L9: - | M9: - | N9: - | O9: - | P9: - | Q9: -
A10: Cuadro | C10: Bioeconomía Productos | D10: Agricultura | E10: Minería | F10: Manufacturas | G10: Servicios básicos y agua | H10: Construcción | I10: Comercio | J10: Otros servicios | K10: Producción / Consumo intermedio Total | L10: - | M10: - | N10: - | O10: - | P10: - | Q10: -
A11: Oferta | B11: Producción | C11: Bioeconomía | D11: 16098751 | E11: 0 | F11: 20489981 | G11: 0 | H11: 0 | I11: 0 | J11: 155114 | K11: =SUM(D11:J11) -> 36743846 | L11: 2625822 | M11: 0 | N11: 1412625 | O11: 7883539 | R11: 48665832
C12: Bioeconomía extendida | D12: 0 | E12: 0 | F12: 4518204 | G12: 572685 | H12: 7251130 | I12: 0 | J12: 4423609 | K12: =SUM(D12:J12) -> 16765628 | L12: 3276955 | M12: 0 | N12: 1112634 | O12: 1786448 | R12: 22941665
C13: No bioeconomía | D13: 139732 | E13: 11440389 | F13: 17428126 | G13: 3747596 | H13: 13113084 | I13: 15642551 | J13: 63012385 | K13: =SUM(D13:J13) -> 124523863 | L13: 20725375 | M13: -1074165 | N13: 5080796 | O13: -9669987 | R13: 139585882
B14: Ajuste CIF/FOB | C14: - | D14: 0 | E14: 0 | F14: 0 | G14: 0 | H14: 0 | I14: 0 | J14: 0 | K14: =SUM(D14:J14) -> 0 | L14: -1074165 | M14: 1074165 | N14: 0 | O14: 0 | R14: 0
A15: Oferta Total | D15: 16238483 | E15: 11440389 | F15: 42436311 | G15: 4320281 | H15: 20364214 | I15: 15642551 | J15: 67591108 | K15: =SUM(D15:J15) -> 178033337 | L15: =SUM(L11:L13) -> 26628152 | M15: 0 | N15: 7606055 | O15: 0 | R15: 211193379
A16: Utilización | B16: Consumo intermedio | C16: Bioeconomía | D16: 2580981 | E16: 91459 | F16: 12109483 | G16: 0 | H16: 1650710 | I16: 19467 | J16: 1483320 | K16: =SUM(D16:J16) -> 17935420 | L16: 11415707 | N16: 0 | P16: 17720786 | Q16: 1593919 | R16: 48665832
C17: Bioeconomía extendida | D17: 1055356 | E17: 243301 | F17: 1720401 | G17: 58698 | H17: 156864 | I17: 417704 | J17: 2278459 | K17: =SUM(D17:J17) -> 5930783 | L17: 331359 | N17: 0 | P17: 9205108 | Q17: 7474415 | R17: 22941665
C18: No bioeconomía | D18: 2976132 | E18: 4938200 | F18: 13606042 | G18: 2551012 | H18: 6431524 | I18: 5041871 | J18: 18666400 | K18: =SUM(D18:J18) -> 54211181 | L18: 12566986 | N18: 0 | P18: 53105616 | Q18: 19702099 | R18: 139585882
B19: Ajuste CIF/FOB | C19: - | D19: 0 | E19: 0 | F19: 0 | G19: 0 | H19: 0 | I19: 0 | J19: 0 | K19: =SUM(D19:J19) -> 0 | L19: 0 | N19: 0 | P19: 0 | Q19: 0 | R19: 0
A20: Utilización Total | D20: 6612469 | E20: 5272960 | F20: 27435926 | G20: 2609710 | H20: 8239098 | I20: 5479042 | J20: 22428179 | K20: =SUM(D20:J20) -> 78077384 | L20: 24314052 | N20: 0 | P20: 80031510 | Q20: 28770433 | R20: 211193379
A21: Valor Agregado | D21: 9626014 | E21: 6167429 | F21: 15000385 | G21: 1710571 | H21: 12125116 | I21: 10163509 | J21: 45162929 | K21: =SUM(D21:J21) -> 99955953 | R21: 99955953
A22: Empleo Total | D22: 1679420 | E22: 53460 | F22: 764792 | G22: 47231 | H22: 562097 | I22: 1826840 | J22: 2649637 | K22: =SUM(D22:J22) -> 7583477 | R22: 7583477
B32: Producción | C32: Bioeconomía | D32: =D11/D$15 -> 0.99139501 | E32: =E11/E$15 -> 0 | F32: =F11/F$15 -> 0.48284077 | G32: =G11/G$15 -> 0 | H32: =H11/H$15 -> 0 | I32: =I11/I$15 -> 0 | J32: =J11/J$15 -> 0.0022948877 | K32: =K11/K$15 -> 0.20638745 | L32: =L11/L$15 -> 0.098610749 | N32: =N11/N$15 -> 0.18572374
C33: Bioeconomía extendida | D33: =D12/D$15 -> 0 | E33: =E12/E$15 -> 0 | F33: =F12/F$15 -> 0.10647023 | G33: =G12/G$15 -> 0.13255735 | H33: =H12/H$15 -> 0.35607218 | I33: =I12/I$15 -> 0 | J33: =J12/J$15 -> 0.065446612 | K33: =K12/K$15 -> 0.094171284 | L33: =L12/L$15 -> 0.12306355 | N33: =N12/N$15 -> 0.14628267
C34: No bioeconomía | D34: =D13/D$15 -> 0.008604991 | E34: =E13/E$15 -> 1 | F34: =F13/F$15 -> 0.410689 | G34: =G13/G$15 -> 0.86744265 | H34: =H13/H$15 -> 0.64392782 | I34: =I13/I$15 -> 1 | J34: =J13/J$15 -> 0.9322585 | K34: =K13/K$15 -> 0.69944127 | L34: =L13/L$15 -> 0.7783257 | N34: =N13/N$15 -> 0.66799359
B35: Ajuste CIF/FOB | C35: -
B37: Consumo intermedio | C37: Bioeconomía | D37: =D16/D$20 -> 0.39032032 | E37: =E16/E$20 -> 0.017344907 | F37: =F16/F$20 -> 0.44137322 | G37: =G16/G$20 -> 0 | H37: =H16/H$20 -> 0.20035082 | I37: =I16/I$20 -> 0.0035529934 | J37: =J16/J$20 -> 0.066136444 | K37: =K16/K$20 -> 0.22971338 | L37: =L16/L$20 -> 0.46951068 | P37: =P16/P$20 -> 0.22142261 | Q37: =Q16/Q$20 -> 0.055401286
C38: Bioeconomía extendida | D38: =D17/D$20 -> 0.1596009 | E38: =E17/E$20 -> 0.046141257 | F38: =F17/F$20 -> 0.062706139 | G38: =G17/G$20 -> 0.022492154 | H38: =H17/H$20 -> 0.019038977 | I38: =I17/I$20 -> 0.076236685 | J38: =J17/J$20 -> 0.10158912 | K38: =K17/K$20 -> 0.075960319 | L38: =L17/L$20 -> 0.013628292 | P38: =P17/P$20 -> 0.11501855 | Q38: =Q17/Q$20 -> 0.25979501
C39: No bioeconomía | D39: =D18/D$20 -> 0.45007878 | E39: =E18/E$20 -> 0.93651384 | F39: =F18/F$20 -> 0.49592064 | G39: =G18/G$20 -> 0.97750785 | H39: =H18/H$20 -> 0.78061021 | I39: =I18/I$20 -> 0.92021032 | J39: =J18/J$20 -> 0.83227443 | K39: =K18/K$20 -> 0.6943263 | L39: =L18/L$20 -> 0.51686103 | P39: =P18/P$20 -> 0.66355884 | Q39: =Q18/Q$20 -> 0.6848037

Sheet GTM
A1: Guatemala | K1: Contenido
A2: Cuadros de oferta y utilización bioeconómica por producto y actividad económica
A3: Año 2018
A4: Precios corrientes
A5: Millones de quetzales
A6: PRELIMINAR NO CITAR
D8: Producción / Consumo intermedio | L8: Exportaciones / Importaciones | M8: Ajuste CIF/FOB | N8: Impuestos menos subvenciones sobre los productos | O8: Márgenes de distribución | P8: Consumo final | Q8: Formación bruta de capital
D9: A | E9: B | F9: C | G9: D - E | H9: F | I9: G | J9: H - S | L9: - | M9: - | N9: - | O9: - | P9: - | Q9: -
A10: Cuadro | C10: Bioeconomía P. | D10: Agricultura | E10: Minería | F10: Manufacturas | G10: Servicios básicos y agua | H10: Construcción | I10: Comercio | J10: Otros servicios | K10: Producción / Consumo intermedio Total | L10: - | M10: - | N10: - | O10: - | P10: - | Q10: -
A11: Oferta | B11: Producción | C11: Bioeconomía | D11: 86305.823 | E11: 0 | F11: 96882.35 | G11: 3763.9925 | H11: 0 | I11: 572.37628 | J11: 274.45237 | K11: =SUM(D11:J11) -> 187798.99 | L11: 29032.066 | M11: 0 | N11: 8880.7577 | O11: 81111.609 | R11: 306823.43
C12: Bioeconomía extendida | D12: 2801.5051 | E12: 0 | F12: 42883.768 | G12: 1963.404 | H12: 0 | I12: 38.066467 | J12: 37906.361 | K12: =SUM(D12:J12) -> 85593.105 | L12: 32378.536 | M12: 0 | N12: 5834.65 | O12: 21961.673 | R12: 145767.96
C13: No Bioeconomía | D13: 3481.1305 | E13: 4978.7684 | F13: 61410.256 | G13: 15820.197 | H13: 55857.769 | I13: 144876.3 | J13: 310743.42 | K13: =SUM(D13:J13) -> 597167.85 | L13: 107115.72 | M13: -9498.5112 | N13: 18802.359 | O13: -103073.28 | R13: 610514.13
B14: Ajuste CIF/FOB oferta | C14: - | D14: 0 | E14: 0 | F14: 0 | G14: 0 | H14: 0 | I14: 0 | J14: 0 | K14: =SUM(D14:J14) -> 0 | L14: -9498.5112 | M14: 9498.5112 | N14: 0 | O14: 0 | R14: 0
A15: Oferta Total | D15: 92588.458 | E15: 4978.7684 | F15: 201176.37 | G15: 21547.594 | H15: 55857.769 | I15: 145486.75 | J15: 348924.23 | K15: =SUM(D15:J15) -> 870559.94 | L15: =SUM(L11:L13) -> 168526.32 | M15: 0 | N15: 33517.767 | O15: -1.9999716e-06 | R15: 1063105.5
A16: Utilización | B16: Consumo intermedio | C16: Bioeconomía | D16: 11826.863 | E16: 22.100133 | F16: 52114.283 | G16: 172.01904 | H16: 85.8228 | I16: 1181.633 | J16: 19606.528 | K16: =SUM(D16:J16) -> 85009.248 | L16: 41559.924 | P16: 178290.44 | Q16: 1963.8185 | R16: 306823.43
C17: Bioeconomía extendida | D17: 15495.213 | E17: 76.996886 | F17: 23235.051 | G17: 364.73785 | H17: 1372.546 | I17: 2480.0808 | J17: 5153.6875 | K17: =SUM(D17:J17) -> 48178.314 | L17: 15406.329 | P17: 81844.149 | Q17: 339.17147 | R17: 145767.96
C18: No Bioeconomía | D18: 13218.317 | E18: 1895.9162 | F18: 48956.85 | G18: 8924.4698 | H18: 28389.42 | I18: 36211.784 | J18: 82823.409 | K18: =SUM(D18:J18) -> 220420.17 | L18: 33856.572 | P18: 282592.96 | Q18: 73644.432 | R18: 610514.13
B19: Ajuste CIF/FOB utilización | C19: - | D19: 0 | E19: 0 | F19: 0 | G19: 0 | H19: 0 | I19: 0 | J19: 0 | K19: =SUM(D19:J19) -> 0 | L19: 9357.0417 | P19: -9357.0417 | Q19: 0 | R19: 0
A20: Utilización Total | D20: 40540.394 | E20: 1995.0132 | F20: 124306.18 | G20: 9461.2267 | H20: 29847.789 | I20: 39873.498 | J20: 107583.62 | K20: =SUM(D20:J20) -> 353607.73 | L20: 100179.87 | P20: 533370.5 | Q20: 75947.422 | R20: 1063105.5
A21: Valor Agregado | D21: 52048.065 | E21: 2983.7552 | F21: 76870.19 | G21: 12086.367 | H21: 26009.98 | I21: 105613.25 | J21: 241340.61 | K21: =SUM(D21:J21) -> 516952.22 | R21: 516952.22
A22: Empleo Total | D22: 2735528 | E22: 30954 | F22: 786582 | G22: 65547 | H22: 371341 | I22: 1522265 | J22: 2294634 | K22: =SUM(D22:J22) -> 7806851 | R22: 7806851
B32: Producción | C32: Bioeconomía | D32: =D11/D$15 -> 0.93214451 | E32: =E11/E$15 -> 0 | F32: =F11/F$15 -> 0.48157916 | G32: =G11/G$15 -> 0.17468273 | H32: =H11/H$15 -> 0 | I32: =I11/I$15 -> 0.003934216 | J32: =J11/J$15 -> 0.00078656722 | K32: =K11/K$15 -> 0.21572207 | L32: =L11/L$15 -> 0.17227022 | N32: =N11/N$15 -> 0.26495672
C33: Bioeconomía extendida | D33: =D12/D$15 -> 0.030257606 | E33: =E12/E$15 -> 0 | F33: =F12/F$15 -> 0.21316503 | G33: =G12/G$15 -> 0.091119408 | H33: =H12/H$15 -> 0 | I33: =I12/I$15 -> 0.00026164904 | J33: =J12/J$15 -> 0.1086378 | K33: =K12/K$15 -> 0.098319599 | L33: =L12/L$15 -> 0.19212747 | N33: =N12/N$15 -> 0.17407633
C34: No Bioeconomía | D34: =D13/D$15 -> 0.037597889 | E34: =E13/E$15 -> 1 | F34: =F13/F$15 -> 0.30525581 | G34: =G13/G$15 -> 0.73419786 | H34: =H13/H$15 -> 1 | I34: =I13/I$15 -> 0.99580413 | J34: =J13/J$15 -> 0.89057563 | K34: =K13/K$15 -> 0.68595833 | L34: =L13/L$15 -> 0.63560231 | N34: =N13/N$15 -> 0.56096694
B35: Ajuste CIF/FOB oferta | C35: -
B37: Consumo intermedio | C37: Bioeconomía | D37: =D16/D$20 -> 0.29173034 | E37: =E16/E$20 -> 0.011077687 | F37: =F16/F$20 -> 0.41924127 | G37: =G16/G$20 -> 0.018181473 | H37: =H16/H$20 -> 0.0028753487 | I37: =I16/I$20 -> 0.029634545 | J37: =J16/J$20 -> 0.18224454 | K37: =K16/K$20 -> 0.24040551 | L37: =L16/L$20 -> 0.41485306 | P37: =P16/P$20 -> 0.33427127 | Q37: =Q16/Q$20 -> 0.025857606
C38: Bioeconomía extendida | D38: =D17/D$20 -> 0.38221665 | E38: =E17/E$20 -> 0.038594674 | F38: =F17/F$20 -> 0.1869179 | G38: =G17/G$20 -> 0.038550799 | H38: =H17/H$20 -> 0.045984846 | I38: =I17/I$20 -> 0.062198726 | J38: =J17/J$20 -> 0.047904014 | K38: =K17/K$20 -> 0.13624791 | L38: =L17/L$20 -> 0.15378668 | P38: =P17/P$20 -> 0.15344709 | Q38: =Q17/Q$20 -> 0.0044658721
C39: No Bioeconomía | D39: =D18/D$20 -> 0.32605301 | E39: =E18/E$20 -> 0.95032764 | F39: =F18/F$20 -> 0.39384083 | G39: =G18/G$20 -> 0.94326773 | H39: =H18/H$20 -> 0.95113981 | I39: =I18/I$20 -> 0.90816673 | J39: =J18/J$20 -> 0.76985145 | K39: =K18/K$20 -> 0.62334658 | L39: =L18/L$20 -> 0.33795784 | P39: =P18/P$20 -> 0.52982487 | Q39: =Q18/Q$20 -> 0.96967652

Sheet HND
A1: Honduras | K1: Contenido
A2: Cuadros de oferta y utilización bioeconómica por producto y actividad económica
A3: Año 2018
A4: Precios corrientes
A5: Millones de lempiras corrientes
A6: PRELIMINAR NO CITAR
D8: Producción / Consumo intermedio | L8: Exportaciones / Importaciones | M8: Ajuste CIF/FOB | N8: Impuestos menos subvenciones sobre los productos | O8: Márgenes de distribución | P8: Consumo final | Q8: Formación bruta de capital
D9: A | E9: B | F9: C | G9: D - E | H9: F | I9: G | J9: H - S | L9: - | M9: - | N9: - | O9: - | P9: - | Q9: -
A10: Cuadro | C10: Bioeconomía Productos | D10: Agricultura | E10: Minería | F10: Manufacturas | G10: Servicios básicos y agua | H10: Construcción | I10: Comercio | J10: Otros servicios | K10: Producción / Consumo intermedio Total | L10: - | M10: - | N10: - | O10: - | P10: - | Q10: -
A11: Oferta | B11: Producción | C11: Bioeconomía | D11: 105475.1 | E11: 0 | F11: 165684 | G11: 0 | H11: 0 | I11: 0 | J11: 18 | K11: =SUM(D11:J11) -> 271177.1 | L11: 46119.4 | M11: 0 | N11: 11645.8 | O11: 60015.3 | R11: 388957.6
C12: Bioeconomía extendida | D12: 128.1 | E12: 0 | F12: 144225.9 | G12: 0.3 | H12: 0 | I12: 48.1 | J12: 76039.1 | K12: =SUM(D12:J12) -> 220441.5 | L12: 152184.7 | M12: -25270.5 | N12: 12063.3 | O12: 11304.4 | R12: 370723.4
C13: No bioeconomía | D13: 7940.6 | E13: 7184.8 | F13: 65106.8 | G13: 35298.1 | H13: 73552.9 | I13: 111484.3 | J13: 286589.2 | K13: =SUM(D13:J13) -> 587156.7 | L13: 181061.8 | M13: -3523.4 | N13: 31351 | O13: -71320 | R13: 724726.1
B14: Ajuste CIF/FOB | C14: - | D14: 0 | E14: 0 | F14: 0 | G14: 0 | H14: 0 | I14: 0 | J14: 0 | K14: =SUM(D14:J14) -> 0 | L14: -28793.9 | M14: 28793.9 | N14: 0 | O14: 0 | R14: 0
B15: Compras directas en el exterior por residentes | C15: - | D15: 0 | E15: 0 | F15: 0 | G15: 0 | H15: 0 | I15: 0 | J15: 0 | K15: =SUM(D15:J15) -> 0 | L15: 6658.9 | M15: 0 | N15: 0 | O15: 0 | R15: 6658.9
A16: Oferta Total | D16: 113543.8 | E16: 7184.8 | F16: 375016.7 | G16: 35298.4 | H16: 73552.9 | I16: 111532.4 | J16: 362646.3 | K16: =SUM(D16:J16) -> 1078775.3 | L16: =SUM(L11:L13) -> 379365.9 | M16: 0 | N16: 55060.1 | O16: -0.3 | R16: 1491066
A17: Utilización | B17: Consumo intermedio | C17: Bioeconomía | D17: 20035.3 | E17: 41.2 | F17: 90904 | G17: 128.6 | H17: 0 | I17: 232.5 | J17: 15019.6 | K17: =SUM(D17:J17) -> 126361.2 | L17: 76023.4 | P17: 171633.5 | Q17: 14939.5 | R17: 388957.6
C18: Bioeconomía extendida | D18: 13548.4 | E18: 372.7 | F18: 119279.9 | G18: 717.5 | H18: 2914.1 | I18: 6891.8 | J18: 19902.1 | K18: =SUM(D18:J18) -> 163626.5 | L18: 106830.8 | P18: 94631.3 | Q18: 5635.3 | R18: 370723.9
C19: No bioeconomía | D19: 13168.7 | E19: 2897.5 | F19: 67651.4 | G19: 17174 | H19: 35988.9 | I19: 23070.3 | J19: 108612 | K19: =SUM(D19:J19) -> 268562.8 | L19: 51424.5 | P19: 272448.2 | Q19: 132290.4 | R19: 724725.9
B20: Ajuste CIF/FOB | C20: - | D20: 0 | E20: 0 | F20: 0 | G20: 0 | H20: 0 | I20: 0 | J20: 0 | K20: =SUM(D20:J20) -> 0 | L20: 0 | P20: 0 | Q20: 0 | R20: 0
B21: Compras directas en el territorio nacional por no residentes | C21: - | D21: 0 | E21: 0 | F21: 0 | G21: 0 | H21: 0 | I21: 0 | J21: 0 | K21: =SUM(D21:J21) -> 0 | L21: 4204.6 | P21: 2454.3 | Q21: 0 | R21: 6658.9
A22: Utilización Total | D22: 46752.4 | E22: 3311.4 | F22: 277835.3 | G22: 18020.1 | H22: 38903 | I22: 30194.6 | J22: 143533.7 | K22: =SUM(D22:J22) -> 558550.5 | L22: 238483.3 | P22: 541167.3 | Q22: 152865.2 | R22: 1491066.3
A23: Valor Agregado | D23: 66791.5 | E23: 3873.4 | F23: 97181.2 | G23: 17278.1 | H23: 34649.7 | I23: 81338 | J23: 219113.3 | K23: =SUM(D23:J23) -> 520225.2 | R23: 520225.2
B33: Producción | C33: Bioeconomía | D33: =D11/D$16 -> 0.92893756 | E33: =E11/E$16 -> 0 | F33: =F11/F$16 -> 0.44180432 | G33: =G11/G$16 -> 0 | H33: =H11/H$16 -> 0 | I33: =I11/I$16 -> 0 | J33: =J11/J$16 -> 4.963514e-05 | K33: =K11/K$16 -> 0.25137496 | L33: =L11/L$16 -> 0.1215697 | N33: =N11/N$16 -> 0.21151069
C34: Bioeconomía extendida | D34: =D12/D$16 -> 0.001128199 | E34: =E12/E$16 -> 0 | F34: =F12/F$16 -> 0.38458527 | G34: =G12/G$16 -> 8.4989688e-06 | H34: =H12/H$16 -> 0 | I34: =I12/I$16 -> 0.00043126482 | J34: =J12/J$16 -> 0.20967841 | K34: =K12/K$16 -> 0.20434422 | L34: =L12/L$16 -> 0.40115545 | N34: =N12/N$16 -> 0.21909332
C35: No bioeconomía | D35: =D13/D$16 -> 0.069934246 | E35: =E13/E$16 -> 1 | F35: =F13/F$16 -> 0.1736104 | G35: =G13/G$16 -> 0.9999915 | H35: =H13/H$16 -> 1 | I35: =I13/I$16 -> 0.99956874 | J35: =J13/J$16 -> 0.79027195 | K35: =K13/K$16 -> 0.54428082 | L35: =L13/L$16 -> 0.47727484 | N35: =N13/N$16 -> 0.56939599
B36: Ajuste CIF/FOB | C36: -
B37: Compras directas en el exterior por residentes | C37: -
B39: Consumo intermedio | C39: Bioeconomía | D39: =D17/D$22 -> 0.42854057 | E39: =E17/E$22 -> 0.012441867 | F39: =F17/F$22 -> 0.32718665 | G39: =G17/G$22 -> 0.0071364754 | H39: =H17/H$22 -> 0 | I39: =I17/I$22 -> 0.0077000523 | J39: =J17/J$22 -> 0.10464163 | K39: =K17/K$22 -> 0.22623057 | L39: =L17/L$22 -> 0.31877872 | P39: =P17/P$22 -> 0.31715423 | Q39: =Q17/Q$22 -> 0.097729895
C40: Bioeconomía extendida | D40: =D18/D$22 -> 0.28979047 | E40: =E18/E$22 -> 0.11255058 | F40: =F18/F$22 -> 0.42931874 | G40: =G18/G$22 -> 0.039816649 | H40: =H18/H$22 -> 0.07490682 | I40: =I18/I$22 -> 0.22824611 | J40: =J18/J$22 -> 0.13865803 | K40: =K18/K$22 -> 0.29294844 | L40: =L18/L$22 -> 0.44795925 | P40: =P18/P$22 -> 0.17486515 | Q40: =Q18/Q$22 -> 0.036864505
C41: No bioeconomía | D41: =D19/D$22 -> 0.28166896 | E41: =E19/E$22 -> 0.87500755 | F41: =F19/F$22 -> 0.24349462 | G41: =G19/G$22 -> 0.95304688 | H41: =H19/H$22 -> 0.92509318 | I41: =I19/I$22 -> 0.76405384 | J41: =J19/J$22 -> 0.75670034 | K41: =K19/K$22 -> 0.48082098 | L41: =L19/L$22 -> 0.21563145 | P41: =P19/P$22 -> 0.50344542 | Q41: =Q19/Q$22 -> 0.8654056

Sheet NIC
A1: Nicaragua | K1: Contenido
A2: Cuadros de oferta y utilización bioeconómica por producto y actividad económica
A3: Año 2018
A4: Precios corrientes
A5: Millones de córdobas
A6: PRELIMINAR NO CITAR
D8: Producción / Consumo intermedio | L8: Exportaciones / Importaciones | M8: Ajuste CIF/FOB | N8: Impuestos menos subvenciones sobre los productos | O8: Márgenes de distribución | P8: Consumo final | Q8: Formación bruta de capital
D9: A | E9: B | F9: C | G9: D - E | H9: F | I9: G | J9: H - S | L9: - | M9: - | N9: - | O9: - | P9: - | Q9: -
A10: Cuadro | C10: Bioeconomía Productos | D10: Agricultura | E10: Minería | F10: Manufacturas | G10: Servicios básicos y agua | H10: Construcción | I10: Comercio | J10: Otros servicios | K10: Producción / Consumo intermedio Total | L10: - | M10: - | N10: - | O10: - | P10: - | Q10: -
A11: Oferta | B11: Producción | C11: Bioeconomía | D11: 103025.57 | E11: 0 | F11: 113640.27 | G11: 0 | H11: 0 | I11: 55.02948 | J11: 46.782275 | K11: =SUM(D11:J11) -> 216767.65 | L11: 33505.562 | M11: 0 | N11: 10427.153 | O11: 32215.214 | R11: 292915.58
C12: Bioeconomía extendida | D12: 0 | E12: 0 | F12: 44068.281 | G12: 3692.4169 | H12: 0 | I12: 205.08521 | J12: 29671.743 | K12: =SUM(D12:J12) -> 77637.526 | L12: 72771.206 | M12: 0 | N12: 5501.2034 | O12: 14546.89 | R12: 170456.83
C13: No bioeconomía | D13: 10.28813 | E13: 17047.581 | F13: 49338.364 | G13: 25719.452 | H13: 66146.373 | I13: 68813.398 | J13: 224565.13 | K13: =SUM(D13:J13) -> 451640.59 | L13: 119885.64 | M13: -13904.152 | N13: 19705.736 | O13: -46762.104 | R13: 530565.71
B14: Ajuste CIF/FOB | C14: - | D14: 0 | E14: 0 | F14: 0 | G14: 0 | H14: 0 | I14: 0 | J14: 0 | K14: =SUM(D14:J14) -> 0 | L14: -13904.152 | M14: 13904.152 | N14: 0 | O14: 0 | R14: 0
B15: Compras directas en el exterior por residentes | C15: - | D15: 0 | E15: 0 | F15: 0 | G15: 0 | H15: 0 | I15: 0 | J15: 0 | K15: =SUM(D15:J15) -> 0 | L15: 253.53192 | M15: 0 | N15: 0 | O15: 0 | R15: 253.53192
A16: Oferta Total | D16: 103035.85 | E16: 17047.581 | F16: 207046.92 | G16: 29411.869 | H16: 66146.373 | I16: 69073.513 | J16: 254283.66 | K16: =SUM(D16:J16) -> 746045.77 | L16: =SUM(L11:L13) -> 226162.41 | M16: 5.0931703e-11 | N16: 35634.093 | O16: -0.00035883913 | R16: 994191.65
A17: Utilización | B17: Consumo intermedio | C17: Bioeconomía | D17: 16598.479 | E17: 108.90647 | F17: 68264.803 | G17: 2.8974343 | H17: 38.839767 | I17: 118.91473 | J17: 12939.094 | K17: =SUM(D17:J17) -> 98071.934 | L17: 76454.428 | P17: 105885.37 | Q17: 12503.85 | R17: 292915.58
C18: Bioeconomía extendida | D18: 11886.306 | E18: 783.22111 | F18: 33716.105 | G18: 491.39267 | H18: 4133.6801 | I18: 2402.0491 | J18: 12481.926 | K18: =SUM(D18:J18) -> 65894.681 | L18: 45097.501 | P18: 62306.591 | Q18: -2841.948 | R18: 170456.83
C19: No bioeconomía | D19: 11578.681 | E19: 5785.5774 | F19: 48161.714 | G19: 15163.588 | H19: 40272.878 | I19: 19002.812 | J19: 66552.922 | K19: =SUM(D19:J19) -> 206518.17 | L19: 47934.536 | P19: 186831.23 | Q19: 89281.773 | R19: 530565.71
B20: Ajuste CIF/FOB | C20: - | D20: 0 | E20: 0 | F20: 0 | G20: 0 | H20: 0 | I20: 0 | J20: 0 | K20: =SUM(D20:J20) -> 0 | L20: 0 | P20: 0 | Q20: 0 | R20: 0
B21: Compras directas en el territorio nacional por no residentes | C21: - | D21: 0 | E21: 0 | F21: 0 | G21: 0 | H21: 0 | I21: 0 | J21: 207.48091 | K21: =SUM(D21:J21) -> 207.48091 | L21: 4267.3645 | P21: -4221.3135 | Q21: 0 | R21: 253.53192
A22: Utilización Total | D22: 40063.466 | E22: 6677.705 | F22: 150142.62 | G22: 15657.878 | H22: 44445.398 | I22: 21523.776 | J22: 92181.423 | K22: =SUM(D22:J22) -> 370692.27 | L22: 173753.83 | P22: 350801.88 | Q22: 98943.675 | R22: 994191.65
A23: Valor Agregado | D23: 62972.387 | E23: 10369.876 | F23: 56904.295 | G23: 13753.991 | H23: 21700.974 | I23: 47549.737 | J23: 162102.24 | K23: =SUM(D23:J23) -> 375353.5 | R23: 375353.5
B33: Producción | C33: Bioeconomía | D33: =D11/D$16 -> 0.99990015 | E33: =E11/E$16 -> 0 | F33: =F11/F$16 -> 0.54886242 | G33: =G11/G$16 -> 0 | H33: =H11/H$16 -> 0 | I33: =I11/I$16 -> 0.00079667991 | J33: =J11/J$16 -> 0.00018397673 | K33: =K11/K$16 -> 0.29055543 | L33: =L11/L$16 -> 0.14814823 | N33: =N11/N$16 -> 0.29261732
C34: Bioeconomía extendida | D34: =D12/D$16 -> 0 | E34: =E12/E$16 -> 0 | F34: =F12/F$16 -> 0.21284201 | G34: =G12/G$16 -> 0.12554173 | H34: =H12/H$16 -> 0 | I34: =I12/I$16 -> 0.0029690861 | J34: =J12/J$16 -> 0.11668757 | K34: =K12/K$16 -> 0.10406537 | L34: =L12/L$16 -> 0.32176526 | N34: =N12/N$16 -> 0.15438034
C35: No bioeconomía | D35: =D13/D$16 -> 9.9850001e-05 | E35: =E13/E$16 -> 1 | F35: =F13/F$16 -> 0.23829558 | G35: =G13/G$16 -> 0.87445827 | H35: =H13/H$16 -> 1 | I35: =I13/I$16 -> 0.99623423 | J35: =J13/J$16 -> 0.88312845 | K35: =K13/K$16 -> 0.6053792 | L35: =L13/L$16 -> 0.53008651 | N35: =N13/N$16 -> 0.55300233
B36: Ajuste CIF/FOB | C36: -
B37: Compras directas en el exterior por residentes | C37: -
B39: Consumo intermedio | C39: Bioeconomía | D39: =D17/D$22 -> 0.41430462 | E39: =E17/E$22 -> 0.016308967 | F39: =F17/F$22 -> 0.45466638 | G39: =G17/G$22 -> 0.00018504643 | H39: =H17/H$22 -> 0.00087387601 | I39: =I17/I$22 -> 0.0055248083 | J39: =J17/J$22 -> 0.14036553 | K39: =K17/K$22 -> 0.26456428 | L39: =L17/L$22 -> 0.44001579 | P39: =P17/P$22 -> 0.30183808 | Q39: =Q17/Q$22 -> 0.12637342
C40: Bioeconomía extendida | D40: =D18/D$22 -> 0.29668692 | E40: =E18/E$22 -> 0.11728897 | F40: =F18/F$22 -> 0.22456052 | G40: =G18/G$22 -> 0.031383096 | H40: =H18/H$22 -> 0.093005805 | I40: =I18/I$22 -> 0.1115998 | J40: =J18/J$22 -> 0.13540609 | K40: =K18/K$22 -> 0.17776114 | L40: =L18/L$22 -> 0.25954824 | P40: =P18/P$22 -> 0.17761191 | Q40: =Q18/Q$22 -> -0.028722888
C41: No bioeconomía | D41: =D19/D$22 -> 0.28900846 | E41: =E19/E$22 -> 0.86640207 | F41: =F19/F$22 -> 0.3207731 | G41: =G19/G$22 -> 0.96843186 | H41: =H19/H$22 -> 0.90612032 | I41: =I19/I$22 -> 0.88287539 | J41: =J19/J$22 -> 0.72197759 | K41: =K19/K$22 -> 0.55711486 | L41: =L19/L$22 -> 0.27587614 | P41: =P19/P$22 -> 0.53258334 | Q41: =Q19/Q$22 -> 0.90234947

Sheet PAN
A1: Panamá | K1: Contenido
A2: Cuadros de oferta y utilización bioeconómica por producto y actividad económica
A3: Año 2017
A4: Precios corrientes
A5: Millones de balboas
A6: PRELIMINAR NO CITAR
D8: Producción / Consumo intermedio | L8: Exportaciones / Importaciones | M8: Ajuste CIF/FOB | N8: Impuestos menos subvenciones sobre los productos | O8: Márgenes de distribución | P8: Consumo final | Q8: Formación bruta de capital
D9: A | E9: B | F9: C | G9: D - E | H9: F | I9: G | J9: H - S | L9: - | M9: - | N9: - | O9: - | P9: - | Q9: -
A10: Cuadro | B10: Áreas Transaccionales Filas Descripción | C10: Bioeconomía Productos | D10: Agricultura | E10: Minería | F10: Manufacturas | G10: Servicios básicos y agua | H10: Construcción | I10: Comercio | J10: Otros servicios | K10: Producción / Consumo intermedio Total | L10: - | M10: - | N10: - | O10: - | P10: - | Q10: -
A11: Oferta | B11: Producción | C11: Bioeconomía | D11: 2496.2368 | E11: 0 | F11: 4520.2975 | G11: 0 | H11: 0 | I11: 1.1195473 | J11: 2.9423703 | K11: =SUM(D11:J11) -> 7020.5962 | L11: 2306.2334 | M11: 0 | N11: 320.03282 | O11: 3161.4648 | R11: 12808.327
C12: Bioeconomía extendida | D12: 57.512803 | E12: 0 | F12: 1257.4333 | G12: 0.85951 | H12: 0 | I12: 34.84601 | J12: 4693.0197 | K12: =SUM(D12:J12) -> 6043.6714 | L12: 8458.9982 | M12: 0 | N12: 538.38651 | O12: 5758.7482 | R12: 20799.804
C13: No bioeconomía | D13: 2.6712525 | E13: 1580.2659 | F13: 3356.8701 | G13: 1783.4897 | H13: 21011.089 | I13: 15700.899 | J13: 38000.728 | K13: =SUM(D13:J13) -> 81436.014 | L13: 17939.65 | M13: -1318.5612 | N13: 1436.7482 | O13: -8920.213 | R13: 90573.637
B14: Ajuste CIF/FOB | C14: - | D14: 0 | E14: 0 | F14: 0 | G14: 0 | H14: 0 | I14: 0 | J14: 0 | K14: =SUM(D14:J14) -> 0 | L14: -1318.5612 | M14: 1318.5612 | N14: 0 | O14: 0 | R14: 0
B15: Compras directas en el exterior por residentes | C15: - | D15: 0 | E15: 0 | F15: 0 | G15: 0 | H15: 0 | I15: 0 | J15: 0 | K15: =SUM(D15:J15) -> 0 | L15: 1163.0754 | M15: 0 | N15: 0 | O15: 0 | R15: 1163.0754
